Workbook
Name IQ_CH: 110000
Name IQ_CQ: 5000
Name IQ_CY: 10000
Name IQ_DAILY: 500000
Name IQ_FH: 100000
Name IQ_FQ: 500
Name IQ_FY: 1000
Name IQ_LTM: 2000
Name IQ_MONTH: 15000
Name IQ_NTM: 6000
Name IQ_WEEK: 50000
Name IQ_YTD: 3000
Name Levered_Raw_Beta: 'Beta Regression '!$J$10
Name Market_Beta: 'Beta Regression '!$J$13
Name Market_Beta_Weight: 'Beta Regression '!$J$14
Name Raw_Beta_Weight: 'Beta Regression '!$J$11

Sheet DCF>

Sheet WACC
B6: Weighted Average Cost of Capital
B8: All figures are INR unless stated otherwise
B10: Peer Comps
G11: Debt / | H11: Debt / | I11: Levered | J11: Unlevered
B12: Name of the Comp | C12: Country | D12: Total Debt | E12: Total Equity | F12: Tax Rate 1 | G12: Equity | H12: Capital | I12: Beta 2 | J12: Beta 3
B14: ITC | C14: India | D14: ='Beta Comps'!F8 -> 303.43 | E14: ='Beta Comps'!E8 -> 614998.63 | F14: 0.3 | G14: =D14/E14 -> 0.00049338321 | H14: =D14/(D14+E14) -> 0.00049313991 | I14: =Levered_Raw_Beta -> 0.61703382 | J14: =I14/(1+(1-F14)*G14) -> 0.61682079
B15: Godfrey Phillips | C15: India | D15: ='Beta Comps'!F9 -> 345.39 | E15: ='Beta Comps'!E9 -> 36850.69 | F15: 0.3 | G15: =D15/E15 -> 0.0093726875 | H15: =D15/(D15+E15) -> 0.0092856559 | I15: ='Beta Regression '!J121 -> 0.96150882 | J15: =I15/(1+(1-F15)*G15) -> 0.9552416
B16: VST Industries | C16: India | D16: ='Beta Comps'!F10 -> 0 | E16: ='Beta Comps'!E10 -> 6213.52 | F16: 0.3 | G16: =D16/E16 -> 0 | H16: =D16/(D16+E16) -> 0 | I16: ='Beta Regression '!J231 -> 0.21693882 | J16: =I16/(1+(1-F16)*G16) -> 0.21693882
E18: Average | F18: =AVERAGE(F14:F16) -> 0.3 | G18: =AVERAGE(G14:G16) -> 0.0032886902 | H18: =AVERAGE(H14:H16) -> 0.0032595986 | I18: =AVERAGE(I14:I16) -> 0.59849382 | J18: =AVERAGE(J14:J16) -> 0.59633374
E19: Median | F19: =MEDIAN(F14:F16) -> 0.3 | G19: =MEDIAN(G14:G16) -> 0.00049338321 | H19: =MEDIAN(H14:H16) -> 0.00049313991 | I19: =MEDIAN(I14:I16) -> 0.61703382 | J19: =MEDIAN(J14:J16) -> 0.61682079
B22: Cost of Debt | G22: Cost of Equity
B24: Pre-Tax Cost of Debt | E24: =60/D14 -> 0.19773918 | G24: Risk Free Rate | J24: 0.06881
B25: Tax Rate | E25: =F19 -> 0.3 | G25: Equity Risk Premium | J25: =Rm!F11-WACC!J24 -> 0.087281667
B26: Post Tax Cost of Debt | E26: =E24*(1-E25) -> 0.13841743 | G26: Levered Beta 4 | J26: =J34 -> 0.61703382
G27: Cost of Equity | J27: =J24+J25*J26 -> 0.12266574
B29: Capital Structure | G29: Levered
D31: Current | E31: Target | G31: Comps Median Unlevered Beta | J31: =J19 -> 0.61682079
B32: Total Debt | C32: =D14 -> 303.43 | D32: =C32/$C$34 -> 0.00049313991 | E32: =H19 -> 0.00049313991 | G32: Target Debt/ Equity | J32: =E36 -> 0.00049338321
B33: Market Capitalization | C33: =E14 -> 614998.63 | D33: =C33/$C$34 -> 0.99950686 | E33: =E34-E32 -> 0.99950686 | G33: Tax Rate | J33: =E25 -> 0.3
B34: Total Capitalization | C34: =SUM(C32:C33) -> 615302.06 | D34: =C34/$C$34 -> 1 | E34: =D34 -> 1 | G34: Levered Beta | J34: =J31*(1+(1-J33)*J32) -> 0.61703382
B36: Debt / Equity | D36: =D32/D33 -> 0.00049338321 | E36: =E32/E33 -> 0.00049338321 | G36: Weighted Average Cost of Capital
B38: 1. Tax Rate considered as Marginal Tax Rate for the country | G38: Cost of Equity | J38: =J27 -> 0.12266574
B39: 2. Levered Beta is based on 5 year monthly data | G39: Equity Weight | J39: =E33 -> 0.99950686
B40: 3. Unlevered Beta = Levered Beta/(1+(1-Tax Rate) x Debt/Equity)
B41: 4. Levered Beta = Unlevered Beta*(1+(1-Tax Rate) x Debt/Equity) | G41: Cost of Debt | J41: =E26 -> 0.13841743
G42: Debt Weight | J42: =E32 -> 0.00049313991
G44: WACC | J44: =(J38*J39)+(J41+J42) -> 0.26151582

Sheet Beta Regression 
A6: # | B6: ITC Regression Beta - 2 Years Weekly
B8: ITC Weekly Returns | F8: NIFTY Returns | I8: Beta Drifting
B10: Date | C10: Closing Price | D10: Return | F10: Closing Price | G10: Return | I10: Levered Raw Beta | J10: =M13 -> 0.61703382 | L10: Beta 1 | M10: =SLOPE(D12:D114,G12:G114) -> 0.62040474
B11: 44850 | C11: 343.48 | F11: 17576.3 | I11: Raw Beta Weight | J11: 0.75 | L11: Beta 2 | M11: =_xlfn.COVARIANCE.S(D11:D114,G11:G114)/_xlfn.VAR.S(G11:G114) -> 0.62040474
B12: 44857 | C12: 343.68 | D12: =C12/C11-1 -> 0.00058227553 | F12: 17786.8 | G12: =F12/F11-1 -> 0.011976355
B13: 44864 | C13: 351.43 | D13: =C13/C12-1 -> 0.022550047 | F13: 18117.15 | G13: =F13/F12-1 -> 0.018572762 | I13: Market Beta | J13: 1 | L13: Beta 3 | M13: =J37 -> 0.61703382
B14: 44871 | C14: 354.17 | D14: =C14/C13-1 -> 0.0077967163 | F14: 18349.7 | G14: =F14/F13-1 -> 0.012835904 | I14: Market Beta Weight | J14: 0.25
B15: 44878 | C15: 338.96 | D15: =C15/C14-1 -> -0.042945478 | F15: 18307.65 | G15: =F15/F14-1 -> -0.0022915906
B16: 44885 | C16: 338.22 | D16: =C16/C15-1 -> -0.0021831485 | F16: 18512.75 | G16: =F16/F15-1 -> 0.011202967 | I16: Adjusted Beta | J16: =(Levered_Raw_Beta*Raw_Beta_Weight)+(Market_Beta*Market_Beta_Weight) -> 0.71277536
B17: 44892 | C17: 335.09 | D17: =C17/C16-1 -> -0.0092543315 | F17: 18696.1 | G17: =F17/F16-1 -> 0.0099039851
B18: 44899 | C18: 339.31 | D18: =C18/C17-1 -> 0.012593632 | F18: 18496.6 | G18: =F18/F17-1 -> -0.010670675
B19: 44906 | C19: 333.05 | D19: =C19/C18-1 -> -0.018449206 | F19: 18269 | G19: =F19/F18-1 -> -0.012304964
B20: 44913 | C20: 324.7 | D20: =C20/C19-1 -> -0.025071311 | F20: 17806.8 | G20: =F20/F19-1 -> -0.025299688 | I20: SUMMARY OUTPUT
B21: 44920 | C21: 329.52 | D21: =C21/C20-1 -> 0.014844472 | F21: 18105.3 | G21: =F21/F20-1 -> 0.016763259
B22: 44927 | C22: 333 | D22: =C22/C21-1 -> 0.010560816 | F22: 17859.45 | G22: =F22/F21-1 -> -0.013578897 | I22: Regression Statistics
B23: 44934 | C23: 326.74 | D23: =C23/C22-1 -> -0.018798799 | F23: 17956.6 | G23: =F23/F22-1 -> 0.0054396972 | I23: Multiple R | J23: 0.37292515
B24: 44941 | C24: 332.55 | D24: =C24/C23-1 -> 0.017781722 | F24: 18027.65 | G24: =F24/F23-1 -> 0.0039567624 | I24: R Square | J24: 0.13907316
B25: 44948 | C25: 343.88 | D25: =C25/C24-1 -> 0.034070065 | F25: 17604.35 | G25: =F25/F24-1 -> -0.023480598 | I25: Adjusted R Square | J25: 0.13063271
B26: 44955 | C26: 378.32 | D26: =C26/C25-1 -> 0.10015122 | F26: 17854.05 | G26: =F26/F25-1 -> 0.014183994 | I26: Standard Error | J26: 0.022470093
B27: 44962 | C27: 369.08 | D27: =C27/C26-1 -> -0.024423768 | F27: 17856.5 | G27: =F27/F26-1 -> 0.00013722377 | I27: Observations | J27: 104
B28: 44969 | C28: 381.05 | D28: =C28/C27-1 -> 0.032431993 | F28: 17944.2 | G28: =F28/F27-1 -> 0.0049113768
B29: 44976 | C29: 382.74 | D29: =C29/C28-1 -> 0.0044351135 | F29: 17465.8 | G29: =F29/F28-1 -> -0.026660425 | I29: ANOVA
B30: 44983 | C30: 382.59 | D30: =C30/C29-1 -> -0.00039191096 | F30: 17594.35 | G30: =F30/F29-1 -> 0.007360098 | J30: df | K30: SS | L30: MS | M30: F | N30: Significance F
B31: 44990 | C31: 385.62 | D31: =C31/C30-1 -> 0.0079197052 | F31: 17412.9 | G31: =F31/F30-1 -> -0.01031297 | I31: Regression | J31: 1 | K31: 0.008319304 | L31: 0.008319304 | M31: 16.476967 | N31: 9.6687417e-05
B32: 44997 | C32: 373.25 | D32: =C32/C31-1 -> -0.032078212 | F32: 17100.05 | G32: =F32/F31-1 -> -0.017966565 | I32: Residual | J32: 102 | K32: 0.051500317 | L32: 0.00050490507
B33: 45004 | C33: 376.38 | D33: =C33/C32-1 -> 0.0083858004 | F33: 16945.05 | G33: =F33/F32-1 -> -0.009064301 | I33: Total | J33: 103 | K33: 0.059819621
B34: 45011 | C34: 381.15 | D34: =C34/C33-1 -> 0.012673362 | F34: 17359.75 | G34: =F34/F33-1 -> 0.024473224
B35: 45018 | C35: 384.98 | D35: =C35/C34-1 -> 0.010048537 | F35: 17599.15 | G35: =F35/F34-1 -> 0.013790521 | J35: Coefficients | K35: Standard Error | L35: t Stat | M35: P-value | N35: Lower 95% | O35: Upper 95% | P35: Lower 95.0% | Q35: Upper 95.0%
B36: 45025 | C36: 393.18 | D36: =C36/C35-1 -> 0.021299808 | F36: 17828 | G36: =F36/F35-1 -> 0.013003469 | I36: Intercept | J36: 0.0015216218 | K36: 0.0022701209 | L36: 0.67028226 | M36: 0.50419263 | N36: -0.0029811522 | O36: 0.0060243957 | P36: -0.0029811522 | Q36: 0.0060243957
B37: 45032 | C37: 405.75 | D37: =C37/C36-1 -> 0.03197009 | F37: 17624.05 | G37: =F37/F36-1 -> -0.01143987 | I37: X Variable 1 | J37: 0.61703382 | K37: 0.15200936 | L37: 4.059183 | M37: 9.6687417e-05 | N37: 0.31552397 | O37: 0.91854367 | P37: 0.31552397 | Q37: 0.91854367
B38: 45039 | C38: 422.94 | D38: =C38/C37-1 -> 0.042365989 | F38: 18065 | G38: =F38/F37-1 -> 0.025019788
B39: 45046 | C39: 426.13 | D39: =C39/C38-1 -> 0.007542441 | F39: 18069 | G39: =F39/F38-1 -> 0.00022142264
B40: 45053 | C40: 417.88 | D40: =C40/C39-1 -> -0.019360289 | F40: 18314.8 | G40: =F40/F39-1 -> 0.013603409
B41: 45060 | C41: 417.28 | D41: =C41/C40-1 -> -0.0014358189 | F41: 18203.4 | G41: =F41/F40-1 -> -0.0060825125
B42: 45067 | C42: 440.88 | D42: =C42/C41-1 -> 0.056556748 | F42: 18499.35 | G42: =F42/F41-1 -> 0.016257952
B43: 45074 | C43: 443.4 | D43: =C43/C42-1 -> 0.005715841 | F43: 18534.1 | G43: =F43/F42-1 -> 0.0018784444
B44: 45081 | C44: 438.45 | D44: =C44/C43-1 -> -0.011163735 | F44: 18563.4 | G44: =F44/F43-1 -> 0.0015808699
B45: 45088 | C45: 453.1 | D45: =C45/C44-1 -> 0.03341316 | F45: 18826 | G45: =F45/F44-1 -> 0.014146115
B46: 45095 | C46: 444.75 | D46: =C46/C45-1 -> -0.018428603 | F46: 18665.5 | G46: =F46/F45-1 -> -0.0085254435
B47: 45102 | C47: 451.6 | D47: =C47/C46-1 -> 0.015401911 | F47: 19189.05 | G47: =F47/F46-1 -> 0.028049074
...

Sheet Beta Comps
B7: S.No. | C7: Name | D7: CMP Rs. | E7: Mar Cap Rs.Cr. | F7: Debt Rs.Cr. | G7: Debt / Eq
B8: 1 | C8: ITC | D8: 491.7 | E8: 614998.63 | F8: 303.43 | G8: 0
B9: 2 | C9: Godfrey Phillips | D9: 7087.5 | E9: 36850.69 | F9: 345.39 | G9: 0.08
B10: 3 | C10: VST Industries | D10: 365.8 | E10: 6213.52 | F10: 0 | G10: 0

Sheet Rm
B6: Return on Markets
B8: Year | C8: Annual
B9: 2000 | C9: -0.1465 | E9: Average Market Return | F9: =AVERAGE(C9:C32) -> 0.15609167
B10: 2001 | C10: -0.1618 | E10: Dividend Yield | F10: 1.25% 1
B11: 2002 | C11: 0.0325 | E11: Total Market Return | F11: =SUM(F9:F10) -> 0.15609167
B12: 2003 | C12: 0.719
B13: 2004 | C13: 0.1068
B14: 2005 | C14: 0.3634
B15: 2006 | C15: 0.3983
B16: 2007 | C16: 0.5477
B17: 2008 | C17: -0.5179
B18: 2009 | C18: 0.7576
B19: 2010 | C19: 0.1795
B20: 2011 | C20: -0.2462
B21: 2012 | C21: 0.277
B22: 2013 | C22: 0.0676
B23: 2014 | C23: 0.3139
... B32: 2023 | C32: 0.1942

Sheet Intrisic Growth
A6: # | B6: Calculation of ROIC | F6: ='Raw FS'!J$2 -> 43891 | G6: ='Raw FS'!K$2 -> 44256 | H6: ='Raw FS'!L$2 -> 44621 | I6: ='Raw FS'!M$2 -> 44986 | J6: ='Raw FS'!N$2 -> 45352
B8: Current Assets
B9: ='Raw FS'!B36 -> Inventories | F9: ='Raw FS'!J36 -> 8879 | G9: ='Raw FS'!K36 -> 10397 | H9: ='Raw FS'!L36 -> 10864 | I9: ='Raw FS'!M36 -> 11771 | J9: ='Raw FS'!N36 -> 14153
B10: ='Raw FS'!B37 -> Trade receivables | F10: ='Raw FS'!J37 -> 2562 | G10: ='Raw FS'!K37 -> 2502 | H10: ='Raw FS'!L37 -> 2462 | I10: ='Raw FS'!M37 -> 2956 | J10: ='Raw FS'!N37 -> 4026
B11: ='Raw FS'!B39 -> Short term loans | F11: ='Raw FS'!J39 -> 6 | G11: ='Raw FS'!K39 -> 7 | H11: ='Raw FS'!L39 -> 11 | I11: ='Raw FS'!M39 -> 13 | J11: ='Raw FS'!N39 -> 31
B12: ='Raw FS'!B40 -> Other asset items | F12: ='Raw FS'!J40 -> 4952 | G12: ='Raw FS'!K40 -> 4015 | H12: ='Raw FS'!L40 -> 6906 | I12: ='Raw FS'!M40 -> 7941 | J12: ='Raw FS'!N40 -> 4531
B13: Total Current Assets | F13: =SUM(F9:F12) -> 16399 | G13: =SUM(G9:G12) -> 16921 | H13: =SUM(H9:H12) -> 20243 | I13: =SUM(I9:I12) -> 22681 | J13: =SUM(J9:J12) -> 22741
B15: Current Liabilities
B16: ='Raw FS'!B13 -> Trade Payables | F16: ='Raw FS'!J13 -> 3630 | G16: ='Raw FS'!K13 -> 4319 | H16: ='Raw FS'!L13 -> 4417 | I16: ='Raw FS'!M13 -> 4659 | J16: ='Raw FS'!N13 -> 4798
B17: ='Raw FS'!B14 -> Advance from Customers | F17: ='Raw FS'!J14 -> 703 | G17: ='Raw FS'!K14 -> 811 | H17: ='Raw FS'!L14 -> 1278 | I17: ='Raw FS'!M14 -> 1295 | J17: ='Raw FS'!N14 -> 886
B18: ='Raw FS'!B15 -> Other liability items | F18: ='Raw FS'!J15 -> 7050 | G18: ='Raw FS'!K15 -> 7666 | H18: ='Raw FS'!L15 -> 8429 | I18: ='Raw FS'!M15 -> 10032 | J18: ='Raw FS'!N15 -> 10877
B19: Total Current Liabilities | F19: =SUM(F16:F18) -> 11383 | G19: =SUM(G16:G18) -> 12796 | H19: =SUM(H16:H18) -> 14124 | I19: =SUM(I16:I18) -> 15986 | J19: =SUM(J16:J18) -> 16561
A21: # | B21: Net Working Capital | F21: =F13-F19 -> 5016 | G21: =G13-G19 -> 4125 | H21: =H13-H19 -> 6119 | I21: =I13-I19 -> 6695 | J21: =J13-J19 -> 6180
B23: Non-Current Assets
B24: ='Raw FS'!B19 -> Land | F24: ='Raw FS'!J19 -> 2797 | G24: ='Raw FS'!K19 -> 2889 | H24: ='Raw FS'!L19 -> 2829 | I24: ='Raw FS'!M19 -> 2830 | J24: ='Raw FS'!N19 -> 2865
B25: ='Raw FS'!B20 -> Building | F25: ='Raw FS'!J20 -> 8161 | G25: ='Raw FS'!K20 -> 8387 | H25: ='Raw FS'!L20 -> 9100 | I25: ='Raw FS'!M20 -> 9789 | J25: ='Raw FS'!N20 -> 10944
B26: ='Raw FS'!B21 -> Plant Machinery | F26: ='Raw FS'!J21 -> 14625 | G26: ='Raw FS'!K21 -> 15307 | H26: ='Raw FS'!L21 -> 16912 | I26: ='Raw FS'!M21 -> 18480 | J26: ='Raw FS'!N21 -> 20718
B27: ='Raw FS'!B22 -> Equipments | F27: ='Raw FS'!J22 -> 40 | G27: ='Raw FS'!K22 -> 41 | H27: ='Raw FS'!L22 -> 44 | I27: ='Raw FS'!M22 -> 44 | J27: ='Raw FS'!N22 -> 53
B28: ='Raw FS'!B23 -> Furniture n fittings | F28: ='Raw FS'!J23 -> 810 | G28: ='Raw FS'!K23 -> 833 | H28: ='Raw FS'!L23 -> 907 | I28: ='Raw FS'!M23 -> 1000 | J28: ='Raw FS'!N23 -> 1068
B29: ='Raw FS'!B24 -> Railway sidings | F29: ='Raw FS'!J24 -> 2 | G29: ='Raw FS'!K24 -> 2 | H29: ='Raw FS'!L24 -> 2 | I29: ='Raw FS'!M24 -> 2 | J29: ='Raw FS'!N24 -> 2
B30: ='Raw FS'!B25 -> Vehicles | F30: ='Raw FS'!J25 -> 184 | G30: ='Raw FS'!K25 -> 180 | H30: ='Raw FS'!L25 -> 179 | I30: ='Raw FS'!M25 -> 189 | J30: ='Raw FS'!N25 -> 192
B31: ='Raw FS'!B26 -> Intangible Assets | F31: ='Raw FS'!J26 -> 684 | G31: ='Raw FS'!K26 -> 2734 | H31: ='Raw FS'!L26 -> 2744 | I31: ='Raw FS'!M26 -> 3490 | J31: ='Raw FS'!N26 -> 3505
B32: ='Raw FS'!B27 -> Other fixed assets | F32: ='Raw FS'!J27 -> 663 | G32: ='Raw FS'!K27 -> 716 | H32: ='Raw FS'!L27 -> 719 | I32: ='Raw FS'!M27 -> 786 | J32: ='Raw FS'!N27 -> 841
B33: Gross Block | F33: =SUM(F24:F32) -> 27966 | G33: =SUM(G24:G32) -> 31089 | H33: =SUM(H24:H32) -> 33436 | I33: =SUM(I24:I32) -> 36610 | J33: =SUM(J24:J32) -> 40188
B34: Acuumulated Depreciation | F34: ='Raw FS'!J29 -> 6252 | G34: ='Raw FS'!K29 -> 7790 | H34: ='Raw FS'!L29 -> 9204 | I34: ='Raw FS'!M29 -> 10757 | J34: ='Raw FS'!N29 -> 12368
A35: # | B35: Net Non-Current Assets | F35: =SUM(F33:F34) -> 34218 | G35: =SUM(G33:G34) -> 38879 | H35: =SUM(H33:H34) -> 42640 | I35: =SUM(I33:I34) -> 47367 | J35: =SUM(J33:J34) -> 52556
A37: # | B37: Invested Capital | F37: =F35+F21 -> 39234 | G37: =G35+G21 -> 43004 | H37: =H35+H21 -> 48759 | I37: =I35+I21 -> 54062 | J37: =J35+J21 -> 58736
B38: EBIT | F38: ='Historical FS'!H27+'Historical FS'!H21 -> 17698.63 | G38: ='Historical FS'!I27+'Historical FS'!I21 -> 15419.19 | H38: ='Historical FS'!J27+'Historical FS'!J21 -> 18890.74 | I38: ='Historical FS'!K27+'Historical FS'!K21 -> 23895.25 | J38: ='Historical FS'!L27+'Historical FS'!L21 -> 24416.17
A40: # | B40: ROIC | F40: =F38/F37 -> 0.4511044 | G40: =G38/G37 -> 0.35855246 | H40: =H38/H37 -> 0.38743083 | I40: =I38/I37 -> 0.44199715 | J40: =J38/J37 -> 0.41569344
A42: # | B42: Calculation of Reinvestment Rate | F42: ='Raw FS'!J$2 -> 43891 | G42: ='Raw FS'!K$2 -> 44256 | H42: ='Raw FS'!L$2 -> 44621 | I42: ='Raw FS'!M$2 -> 44986 | J42: ='Raw FS'!N$2 -> 45352
B44: Net Capex | F44: =-SUM('Raw FS'!J54:J55) -> 2414 | G44: =-SUM('Raw FS'!K54:K55) -> 1834 | H44: =-SUM('Raw FS'!L54:L55) -> 2009 | I44: =-SUM('Raw FS'!M54:M55) -> 2694 | J44: =-SUM('Raw FS'!N54:N55) -> 3456
B45: Change in Working Capital | G45: =G21-F21 -> -891 | H45: =H21-G21 -> 1994 | I45: =I21-H21 -> 576 | J45: =J21-I21 -> -515
B47: EBIT | F47: =F38 -> 17698.63 | G47: =G38 -> 15419.19 | H47: =H38 -> 18890.74 | I47: =I38 -> 23895.25 | J47: =J38 -> 24416.17
B48: Marginal Tax Rate | F48: 0.3 | G48: 0.3 | H48: 0.3 | I48: 0.3 | J48: 0.3
B49: EBIT{1-T} | F49: =F47*(1-F48) -> 12389.041 | G49: =G47*(1-G48) -> 10793.433 | H49: =H47*(1-H48) -> 13223.518 | I49: =I47*(1-I48) -> 16726.675 | J49: =J47*(1-J48) -> 17091.319
B51: Reinvestment | G51: =SUM(G44:G45) -> 943 | H51: =SUM(H44:H45) -> 4003 | I51: =SUM(I44:I45) -> 3270 | J51: =SUM(J44:J45) -> 2941
B53: Reinvestment Rate | G53: =G51/G49 -> 0.087367939 | H53: =H51/H49 -> 0.30271823 | I53: =I51/I49 -> 0.19549612 | J53: =J51/J49 -> 0.17207566
I55: 4 Year Average | J55: =AVERAGE(G53:J53) -> 0.18941449
I56: 4 year Median | J56: =MEDIAN(G53:J53) -> 0.18378589
A58: # | B58: Calculation of ROIC | F58: ='Raw FS'!J$2 -> 43891 | G58: ='Raw FS'!K$2 -> 44256 | H58: ='Raw FS'!L$2 -> 44621 | I58: ='Raw FS'!M$2 -> 44986 | J58: ='Raw FS'!N$2 -> 45352
...

Sheet DCF
B6: Calculation of PV of FCFF | E6: ='Intrisic Growth'!J6 -> 45352 | F6: =E6+365 -> 45717 | G6: =F6+365 -> 46082 | H6: =G6+365 -> 46447 | I6: =H6+366 -> 46813 | J6: =I6+365 -> 47178
B8: EBIT | E8: ='Data Sheet'!K34-'Data Sheet'!K26 -> 26927.36 | F8: =E8*(1-$C$18) -> 26001.059 | G8: =F8*(1-$C$18) -> 25106.622 | H8: =G8*(1-$C$18) -> 24242.955 | I8: =H8*(1-$C$18) -> 23408.997 | J8: =I8*(1-$C$18) -> 22603.727
B9: Tax Rate | E9: 0.3 | F9: =E9 -> 0.3 | G9: =F9 -> 0.3 | H9: =G9 -> 0.3 | I9: =H9 -> 0.3 | J9: =I9 -> 0.3
B10: EBIT(1-T) | E10: =E8*(1-E9) -> 18849.152 | F10: =F8*(1-F9) -> 18200.741 | G10: =G8*(1-G9) -> 17574.636 | H10: =H8*(1-H9) -> 16970.068 | I10: =I8*(1-I9) -> 16386.298 | J10: =J8*(1-J9) -> 15822.609
B11: Less: Reinvestment rate | E11: ='Intrisic Growth'!J56 -> 0.18378589 | F11: =E11+(($J$11-$E$11)/4) -> 0.26068942 | G11: =F11+(($J$11-$E$11)/4) -> 0.33759294 | H11: =G11+(($J$11-$E$11)/4) -> 0.41449647 | I11: =H11+(($J$11-$E$11)/4) -> 0.4914 | J11: 0.4914
B12: Free Cash Flow to Firm (FCFF) | E12: =E10*(1-E11) -> 15384.944 | F12: =F10*(1-F11) -> 13456.001 | G12: =G10*(1-G11) -> 11641.563 | H12: =H10*(1-H11) -> 9936.0348 | I12: =I10*(1-I11) -> 8334.0711 | J12: =J10*(1-J11) -> 8047.379
B13: Mid Year Convention | F13: 0.5 | G13: =F13+1 -> 1.5 | H13: =G13+1 -> 2.5 | I13: =H13+1 -> 3.5 | J13: =I13+1 -> 4.5
B14: Discounting Factor | F14: =1/(1+$C$20)^F13 -> 0.89033542 | G14: =1/(1+$C$20)^G13 -> 0.70576635 | H14: =1/(1+$C$20)^H13 -> 0.55945898 | I14: =1/(1+$C$20)^I13 -> 0.44348154 | J14: =1/(1+$C$20)^J13 -> 0.35154656
B16: PV of FCFF | F16: =F12*F14 -> 11980.354 | G16: =G12*G14 -> 8216.2232 | H16: =H12*H14 -> 5558.8039 | I16: =I12*I14 -> 3696.0067 | J16: =J12*J14 -> 2829.0284
B18: Expected Growth | C18: 0.0344
B19: Terminal Growth | C19: 0.076
B20: WACC | C20: =WACC!J44 -> 0.26151582
B22: Calculation of Terminal Value
B24: FCFF(n+1) | C24: =J12*(1+C18) -> 8324.2089
B25: WACC | C25: =C20 -> 0.26151582
B26: Terminal Growth rate | C26: =C19 -> 0.076
B28: Terminal Value | C28: =C24/(C25-C26) -> 44870.616
B30: Calculation of Equity Value per Share
B32: PV of FCFF | C32: =SUM(F16:J16) -> 32280.416
B33: PV of Terminal value | C33: =C28*J14 -> 15774.111
B34: Value of Operating Assets | C34: =SUM(C32:C33) -> 48054.527
B36: Add: Cash | C36: ='Data Sheet'!K69 -> 7217.68
B37: Less: Debt | C37: =SUM('Raw FS'!N7:N8) -> 12
B38: Value of Equity | C38: =C34+C36-C37 -> 55260.207
B39: No. of Share | C39: ='Data Sheet'!B6 -> 1250.7599
B41: Equity Value per Share | C41: =C38/C39 -> 44.181308
B43: Share Price | C43: 3079
B44: Discount/Premium | C44: =C43/C41 -> 69.690106

Sheet Financials>

Sheet Historical FS
B2: ="Historical Financial Statement - "&'Data Sheet'!$B$1 -> Historical Financial Statement - ITC LTD
B3: Years | C3: ='Data Sheet'!B$16 -> 42094 | D3: ='Data Sheet'!C$16 -> 42460 | E3: ='Data Sheet'!D$16 -> 42825 | F3: ='Data Sheet'!E$16 -> 43190 | G3: ='Data Sheet'!F$16 -> 43555 | H3: ='Data Sheet'!G$16 -> 43921 | I3: ='Data Sheet'!H$16 -> 44286 | J3: ='Data Sheet'!I$16 -> 44651 | ... L3: ='Data Sheet'!K$16 -> 45382 | M3: LTM
A5: # | B5: Income Statement
B6: Sales | C6: =IFERROR('Data Sheet'!B17,0) -> 38817.15 | D6: =IFERROR('Data Sheet'!C17,0) -> 39192.1 | E6: =IFERROR('Data Sheet'!D17,0) -> 42767.6 | F6: =IFERROR('Data Sheet'!E17,0) -> 43448.94 | G6: =IFERROR('Data Sheet'!F17,0) -> 48339.58 | H6: =IFERROR('Data Sheet'!G17,0) -> 49387.7 | I6: =IFERROR('Data Sheet'!H17,0) -> 49257.45 | J6: =IFERROR('Data Sheet'!I17,0) -> 60644.54 | ... L6: =IFERROR('Data Sheet'!K17,0) -> 70866.22 | M6: =IFERROR(SUM('Data Sheet'!H42:K42),0) -> 72173.87
B7: Sales Growth | C7: - | D7: =D6/C6-1 -> 0.0096593902 | E7: =E6/D6-1 -> 0.09123012 | F7: =F6/E6-1 -> 0.015931219 | G7: =G6/F6-1 -> 0.11256063 | H7: =H6/G6-1 -> 0.021682439 | I7: =I6/H6-1 -> -0.0026372963 | J7: =J6/I6-1 -> 0.23117498 | K7: =K6/J6-1 -> 0.16942152 | ... M7: =M6/L6-1 -> 0.018452374
B9: COGS | C9: =IFERROR(SUM('Data Sheet'!B18,'Data Sheet'!B20,'Data Sheet'!B21,'Data Sheet'!B22)-1*'Data Sheet'!B19,0) -> 19688.38 | D9: =IFERROR(SUM('Data Sheet'!C18,'Data Sheet'!C20,'Data Sheet'!C21,'Data Sheet'!C22)-1*'Data Sheet'!C19,0) -> 19162.94 | E9: =IFERROR(SUM('Data Sheet'!D18,'Data Sheet'!D20,'Data Sheet'!D21,'Data Sheet'!D22)-1*'Data Sheet'!D19,0) -> 21949.12 | F9: =IFERROR(SUM('Data Sheet'!E18,'Data Sheet'!E20,'Data Sheet'!E21,'Data Sheet'!E22)-1*'Data Sheet'!E19,0) -> 21967.5 | G9: =IFERROR(SUM('Data Sheet'!F18,'Data Sheet'!F20,'Data Sheet'!F21,'Data Sheet'!F22)-1*'Data Sheet'!F19,0) -> 24215.95 | H9: =IFERROR(SUM('Data Sheet'!G18,'Data Sheet'!G20,'Data Sheet'!G21,'Data Sheet'!G22)-1*'Data Sheet'!G19,0) -> 24330.4 | I9: =IFERROR(SUM('Data Sheet'!H18,'Data Sheet'!H20,'Data Sheet'!H21,'Data Sheet'!H22)-1*'Data Sheet'!H19,0) -> 26881.51 | J9: =IFERROR(SUM('Data Sheet'!I18,'Data Sheet'!I20,'Data Sheet'!I21,'Data Sheet'!I22)-1*'Data Sheet'!I19,0) -> 34053.06 | ... L9: =IFERROR(SUM('Data Sheet'!K18,'Data Sheet'!K20,'Data Sheet'!K21,'Data Sheet'!K22)-1*'Data Sheet'!K19,0) -> 37015.48 | M9: =IFERROR(SUM('Data Sheet'!H43:K43),0) -> 45841.18
B10: COGS % Sales | C10: =C9/C6 -> 0.50720828 | D10: =D9/D6 -> 0.48894905 | E10: =E9/E6 -> 0.51321842 | F10: =F9/F6 -> 0.50559346 | G10: =G9/G6 -> 0.50095491 | H10: =H9/H6 -> 0.49264088 | I10: =I9/I6 -> 0.54573491 | J10: =J9/J6 -> 0.56151898 | ... M10: =M9/M6 -> 0.63514926
B12: Gross Profit | C12: =C6-C9 -> 19128.77 | D12: =D6-D9 -> 20029.16 | E12: =E6-E9 -> 20818.48 | F12: =F6-F9 -> 21481.44 | G12: =G6-G9 -> 24123.63 | H12: =H6-H9 -> 25057.3 | I12: =I6-I9 -> 22375.94 | J12: =J6-J9 -> 26591.48 | ... M12: =M6-M9 -> 26332.69
B13: Gross Margins | C13: =C12/C6 -> 0.49279172 | D13: =D12/D6 -> 0.51105095 | E13: =E12/E6 -> 0.48678158 | F13: =F12/F6 -> 0.49440654 | G13: =G12/G6 -> 0.49904509 | H13: =H12/H6 -> 0.50735912 | I13: =I12/I6 -> 0.45426509 | J13: =J12/J6 -> 0.43848102 | ... M13: =M12/M6 -> 0.36485074
B15: Selling & General Expenses | C15: =IFERROR(SUM('Data Sheet'!B23:B24),0) -> 4877.15 | D15: =IFERROR(SUM('Data Sheet'!C23:C24),0) -> 5497.67 | E15: =IFERROR(SUM('Data Sheet'!D23:D24),0) -> 5348.97 | F15: =IFERROR(SUM('Data Sheet'!E23:E24),0) -> 4960.85 | G15: =IFERROR(SUM('Data Sheet'!F23:F24),0) -> 5586.24 | H15: =IFERROR(SUM('Data Sheet'!G23:G24),0) -> 5713.76 | I15: =IFERROR(SUM('Data Sheet'!H23:H24),0) -> 5311.16 | J15: =IFERROR(SUM('Data Sheet'!I23:I24),0) -> 5968.33 | ... L15: =IFERROR(SUM('Data Sheet'!K23:K24),0) -> 7618.18
B16: S&G Exp % Sales | C16: =C15/C6 -> 0.12564421 | D16: =D15/D6 -> 0.14027495 | E16: =E15/E6 -> 0.12507061 | F16: =F15/F6 -> 0.11417655 | G16: =G15/G6 -> 0.11556244 | H16: =H15/H6 -> 0.11569196 | I16: =I15/I6 -> 0.1078245 | J16: =J15/J6 -> 0.09841496 | ... M16: =M15/M6 -> 0
B18: EBITDA | C18: =C12-C15 -> 14251.62 | D18: =D12-D15 -> 14531.49 | E18: =E12-E15 -> 15469.51 | F18: =F12-F15 -> 16520.59 | G18: =G12-G15 -> 18537.39 | H18: =H12-H15 -> 19343.54 | I18: =I12-I15 -> 17064.78 | J18: =J12-J15 -> 20623.15 | ... L18: =L12-L15 -> 26232.56 | M18: =IFERROR(SUM('[1]Data Sheet'!H51:K51),0) -> 27983.82
B19: EBITDA Margins | C19: =C18/C6 -> 0.36714751 | D19: =D18/D6 -> 0.370776 | E19: =E18/E6 -> 0.36171097 | F19: =F18/F6 -> 0.38022999 | G19: =G18/G6 -> 0.38348265 | H19: =H18/H6 -> 0.39166716 | I19: =I18/I6 -> 0.34644059 | J19: =J18/J6 -> 0.34006606 | ... M19: =M18/M6 -> 0.38772786
B21: Interest | C21: =IFERROR('Data Sheet'!B27,0) -> 90.96 | D21: =IFERROR('Data Sheet'!C27,0) -> 78.13 | E21: =IFERROR('Data Sheet'!D27,0) -> 49.03 | F21: =IFERROR('Data Sheet'!E27,0) -> 115.01 | G21: =IFERROR('Data Sheet'!F27,0) -> 71.4 | H21: =IFERROR('Data Sheet'!G27,0) -> 81.38 | I21: =IFERROR('Data Sheet'!H27,0) -> 57.97 | J21: =IFERROR('Data Sheet'!I27,0) -> 59.99 | ... L21: =IFERROR('Data Sheet'!K27,0) -> 80.06 | M21: =IFERROR(SUM('Data Sheet'!H46:K46),0) -> 47.31
B22: Interest % Sales | C22: =C21/C6 -> 0.0023432941 | D22: =D21/D6 -> 0.001993514 | E22: =E21/E6 -> 0.0011464286 | F22: =F21/F6 -> 0.0026470151 | G22: =G21/G6 -> 0.0014770505 | H22: =H21/H6 -> 0.0016477787 | I22: =I21/I6 -> 0.0011768778 | J22: =J21/J6 -> 0.00098920694 | ... M22: =M21/M6 -> 0.00065550039
B24: Depreciation | C24: =IFERROR('Data Sheet'!B26,0) -> 1027.96 | D24: =IFERROR('Data Sheet'!C26,0) -> 1077.4 | E24: =IFERROR('Data Sheet'!D26,0) -> 1152.79 | F24: =IFERROR('Data Sheet'!E26,0) -> 1236.28 | G24: =IFERROR('Data Sheet'!F26,0) -> 1396.61 | H24: =IFERROR('Data Sheet'!G26,0) -> 1644.91 | I24: =IFERROR('Data Sheet'!H26,0) -> 1645.59 | J24: =IFERROR('Data Sheet'!I26,0) -> 1732.41 | ... L24: =IFERROR('Data Sheet'!K26,0) -> 1816.39 | M24: =IFERROR(SUM('Data Sheet'!H45:K45),0) -> 1872.5
B25: Depreciation%Sales | C25: =C24/C6 -> 0.026482109 | D25: =D24/D6 -> 0.027490234 | E25: =E24/E6 -> 0.026954751 | F25: =F24/F6 -> 0.028453629 | G25: =G24/G6 -> 0.028891645 | H25: =H24/H6 -> 0.033306066 | I25: =I24/I6 -> 0.033407941 | J25: =J24/J6 -> 0.028566628 | ... M25: =M24/M6 -> 0.025944293
B27: Earnings Before Tax | C27: =IFERROR(C18-SUM(C24,C21),0) -> 13132.7 | D27: =IFERROR(D18-SUM(D24,D21),0) -> 13375.96 | E27: =IFERROR(E18-SUM(E24,E21),0) -> 14267.69 | F27: =IFERROR(F18-SUM(F24,F21),0) -> 15169.3 | G27: =IFERROR(G18-SUM(G24,G21),0) -> 17069.38 | H27: =IFERROR(H18-SUM(H24,H21),0) -> 17617.25 | I27: =IFERROR(I18-SUM(I24,I21),0) -> 15361.22 | J27: =IFERROR(J18-SUM(J24,J21),0) -> 18830.75 | ... M27: =IFERROR(M18-SUM(M24,M21),0) -> 26064.01
B28: EBT % Sales | C28: =C27/C6 -> 0.33832211 | D28: =D27/D6 -> 0.34129225 | E28: =E27/E6 -> 0.33360979 | F28: =F27/F6 -> 0.34912935 | G28: =G27/G6 -> 0.35311395 | H28: =H27/H6 -> 0.35671331 | I28: =I27/I6 -> 0.31185577 | J28: =J27/J6 -> 0.31051023 | ... M28: =M27/M6 -> 0.36112806
B30: Tax | C30: =IFERROR('Data Sheet'!B29,0) -> 4596.42 | D30: =IFERROR('Data Sheet'!C29,0) -> 5358.21 | E30: =IFERROR('Data Sheet'!D29,0) -> 5549.09 | F30: =IFERROR('Data Sheet'!E29,0) -> 5916.43 | G30: =IFERROR('Data Sheet'!F29,0) -> 6313.92 | H30: =IFERROR('Data Sheet'!G29,0) -> 4441.79 | I30: =IFERROR('Data Sheet'!H29,0) -> 4555.29 | J30: =IFERROR('Data Sheet'!I29,0) -> 5237.34 | ... L30: =IFERROR('Data Sheet'!K29,0) -> 6388.52 | M30: =IFERROR(SUM('Data Sheet'!H48:K48),0) -> 6389.69
B31: Effective Tax Rate | C31: =C30/C27 -> 0.3499981 | D31: =D30/D27 -> 0.40058508 | E31: =E30/E27 -> 0.38892701 | F31: =F30/F27 -> 0.39002657 | G31: =G30/G27 -> 0.36989744 | H31: =H30/H27 -> 0.25212732 | I31: =I30/I27 -> 0.29654481 | J31: =J30/J27 -> 0.278127 | ... M31: =M30/M27 -> 0.24515376
B33: Net Profit | C33: =IFERROR(C27-C30,0) -> 8536.28 | D33: =IFERROR(D27-D30,0) -> 8017.75 | E33: =IFERROR(E27-E30,0) -> 8718.6 | F33: =IFERROR(F27-F30,0) -> 9252.87 | G33: =IFERROR(G27-G30,0) -> 10755.46 | H33: =IFERROR(H27-H30,0) -> 13175.46 | I33: =IFERROR(I27-I30,0) -> 10805.93 | J33: =IFERROR(J27-J30,0) -> 13593.41 | ... M33: =IFERROR(M27-M30,0) -> 19674.32
B34: Net Margins | C34: =C33/C6 -> 0.21991001 | D34: =D33/D6 -> 0.20457567 | E34: =E33/E6 -> 0.20385993 | F34: =F33/F6 -> 0.21295963 | G34: =G33/G6 -> 0.222498 | H34: =H33/H6 -> 0.26677614 | I34: =I33/I6 -> 0.21937656 | J34: =J33/J6 -> 0.22414895 | ... M34: =M33/M6 -> 0.27259616
B36: No of Equity Shares | C36: =IFERROR('Data Sheet'!B93,0) -> 1202.33 | D36: =IFERROR('Data Sheet'!C93,0) -> 1207.08 | E36: =IFERROR('Data Sheet'!D93,0) -> 1214.74 | F36: =IFERROR('Data Sheet'!E93,0) -> 1220.43 | G36: =IFERROR('Data Sheet'!F93,0) -> 1225.86 | H36: =IFERROR('Data Sheet'!G93,0) -> 1229.22 | I36: =IFERROR('Data Sheet'!H93,0) -> 1230.88 | J36: =IFERROR('Data Sheet'!I93,0) -> 1232.33 | ... L36: =IFERROR('Data Sheet'!K93,0) -> 1248.47 | M36: =L36 -> 1248.47
B38: Earnings per Share | C38: =IFERROR(C33/C36,0) -> 7.0997813 | D38: =IFERROR(D33/D36,0) -> 6.6422689 | E38: =IFERROR(E33/E36,0) -> 7.1773384 | F38: =IFERROR(F33/F36,0) -> 7.5816475 | G38: =IFERROR(G33/G36,0) -> 8.7738078 | H38: =IFERROR(H33/H36,0) -> 10.718553 | I38: =IFERROR(I33/I36,0) -> 8.779028 | J38: =IFERROR(J33/J36,0) -> 11.030657 | ... M38: =IFERROR(M33/M36,0) -> 15.758745
B39: EPS Growth % | D39: =IFERROR(D38/C38-1,0) -> -0.064440339 | E39: =IFERROR(E38/D38-1,0) -> 0.080555217 | F39: =IFERROR(F38/E38-1,0) -> 0.056331341 | G39: =IFERROR(G38/F38-1,0) -> 0.15724291 | H39: =IFERROR(H38/G38-1,0) -> 0.22165353 | I39: =IFERROR(I38/H38-1,0) -> -0.18095028 | J39: =IFERROR(J38/I38-1,0) -> 0.25647821 | K39: =IFERROR(K38/J38-1,0) -> 0.26772234 | ... M39: =IFERROR(M38/L38-1,0) -> 0.096209575
B41: Dividend per Share | C41: =IFERROR('Data Sheet'!B31/'Historical FS'!D36,0) -> 4.1502552 | D41: =IFERROR('Data Sheet'!C31/'Historical FS'!E36,0) -> 5.6309334 | E41: =IFERROR('Data Sheet'!D31/'Historical FS'!F36,0) -> 4.7278582 | F41: =IFERROR('Data Sheet'!E31/'Historical FS'!G36,0) -> 5.1271842 | G41: =IFERROR('Data Sheet'!F31/'Historical FS'!H36,0) -> 5.7342868 | H41: =IFERROR('Data Sheet'!G31/'Historical FS'!I36,0) -> 10.136309 | I41: =IFERROR('Data Sheet'!H31/'Historical FS'!J36,0) -> 10.737351 | J41: =IFERROR('Data Sheet'!I31/'Historical FS'!K36,0) -> 11.403122 | ... M41: =IFERROR('Data Sheet'!L31/'Historical FS'!N36,0) -> 0
B42: Dividend payout ratio | C42: =IFERROR(C41/C38,0) -> 0.58456099 | D42: =IFERROR(D41/D38,0) -> 0.84774245 | E42: =IFERROR(E41/E38,0) -> 0.65872026 | F42: =IFERROR(F41/F38,0) -> 0.67626254 | G42: =IFERROR(G41/G38,0) -> 0.65356877 | H42: =IFERROR(H41/H38,0) -> 0.94567884 | I42: =IFERROR(I41/I38,0) -> 1.2230683 | J42: =IFERROR(J41/J38,0) -> 1.0337663 | ... M42: =IFERROR(M41/M38,0) -> 0
B44: Retained Earnings | C44: =IFERROR(IF(C38>C41,1-C42,0),0) -> 0.41543901 | D44: =IFERROR(IF(D38>D41,1-D42,0),0) -> 0.15225755 | E44: =IFERROR(IF(E38>E41,1-E42,0),0) -> 0.34127974 | F44: =IFERROR(IF(F38>F41,1-F42,0),0) -> 0.32373746 | G44: =IFERROR(IF(G38>G41,1-G42,0),0) -> 0.34643123 | H44: =IFERROR(IF(H38>H41,1-H42,0),0) -> 0.05432116 | I44: =IFERROR(IF(I38>I41,1-I42,0),0) -> 0 | J44: =IFERROR(IF(J38>J41,1-J42,0),0) -> 0 | ... M44: =IFERROR(IF(M38>M41,1-M42,0),0) -> 1
A46: # | B46: Balance Sheet
B47: Equity Share Capital | C47: =IFERROR('Data Sheet'!B57,0) -> 801.55 | D47: =IFERROR('Data Sheet'!C57,0) -> 804.72 | E47: =IFERROR('Data Sheet'!D57,0) -> 1214.74 | F47: =IFERROR('Data Sheet'!E57,0) -> 1220.43 | G47: =IFERROR('Data Sheet'!F57,0) -> 1225.86 | H47: =IFERROR('Data Sheet'!G57,0) -> 1229.22 | I47: =IFERROR('Data Sheet'!H57,0) -> 1230.88 | J47: =IFERROR('Data Sheet'!I57,0) -> 1232.33 | ... L47: =IFERROR('Data Sheet'!K57,0) -> 1248.47
B48: Reserves | C48: =IFERROR('Data Sheet'!B58,0) -> 30933.94 | D48: =IFERROR('Data Sheet'!C58,0) -> 41874.8 | E48: =IFERROR('Data Sheet'!D58,0) -> 45198.19 | F48: =IFERROR('Data Sheet'!E58,0) -> 51289.68 | G48: =IFERROR('Data Sheet'!F58,0) -> 57915.01 | H48: =IFERROR('Data Sheet'!G58,0) -> 64044.04 | I48: =IFERROR('Data Sheet'!H58,0) -> 59116.46 | J48: =IFERROR('Data Sheet'!I58,0) -> 61223.24 | ... L48: =IFERROR('Data Sheet'!K58,0) -> 73258.53
B49: Borrowings | C49: =IFERROR('Data Sheet'!B59,0) -> 268.8 | D49: =IFERROR('Data Sheet'!C59,0) -> 83.78 | E49: =IFERROR('Data Sheet'!D59,0) -> 45.72 | F49: =IFERROR('Data Sheet'!E59,0) -> 35.92 | G49: =IFERROR('Data Sheet'!F59,0) -> 13.44 | H49: =IFERROR('Data Sheet'!G59,0) -> 277.45 | I49: =IFERROR('Data Sheet'!H59,0) -> 270.83 | J49: =IFERROR('Data Sheet'!I59,0) -> 249.44 | ... L49: =IFERROR('Data Sheet'!K59,0) -> 303.43
B50: Other Liabilities | C50: =IFERROR('Data Sheet'!B60,0) -> 13947.93 | D50: =IFERROR('Data Sheet'!C60,0) -> 8888.04 | E50: =IFERROR('Data Sheet'!D60,0) -> 9439.67 | F50: =IFERROR('Data Sheet'!E60,0) -> 11694.85 | G50: =IFERROR('Data Sheet'!F60,0) -> 12584.73 | H50: =IFERROR('Data Sheet'!G60,0) -> 11760.04 | I50: =IFERROR('Data Sheet'!H60,0) -> 13142.59 | J50: =IFERROR('Data Sheet'!I60,0) -> 14491.01 | ... L50: =IFERROR('Data Sheet'!K60,0) -> 16943.54
B51: Total Liabilities | C51: =IFERROR('Data Sheet'!B61,0) -> 45952.22 | D51: =IFERROR('Data Sheet'!C61,0) -> 51651.34 | E51: =IFERROR('Data Sheet'!D61,0) -> 55898.32 | F51: =IFERROR('Data Sheet'!E61,0) -> 64240.88 | G51: =IFERROR('Data Sheet'!F61,0) -> 71739.04 | H51: =IFERROR('Data Sheet'!G61,0) -> 77310.75 | I51: =IFERROR('Data Sheet'!H61,0) -> 73760.76 | J51: =IFERROR('Data Sheet'!I61,0) -> 77196.02 | ... L51: =IFERROR('Data Sheet'!K61,0) -> 91753.97
B53: Fixed Assets Net Block | C53: =IFERROR('Data Sheet'!B62,0) -> 15303.28 | D53: =IFERROR('Data Sheet'!C62,0) -> 15106.63 | E53: =IFERROR('Data Sheet'!D62,0) -> 15893.48 | F53: =IFERROR('Data Sheet'!E62,0) -> 16523.96 | G53: =IFERROR('Data Sheet'!F62,0) -> 19374.19 | H53: =IFERROR('Data Sheet'!G62,0) -> 21713.34 | I53: =IFERROR('Data Sheet'!H62,0) -> 23298.48 | J53: =IFERROR('Data Sheet'!I62,0) -> 24231.59 | ... L53: =IFERROR('Data Sheet'!K62,0) -> 27820.22
B54: Capital Work in Progress | C54: =IFERROR('Data Sheet'!B63,0) -> 2700.2 | D54: =IFERROR('Data Sheet'!C63,0) -> 2559.72 | E54: =IFERROR('Data Sheet'!D63,0) -> 3729.89 | F54: =IFERROR('Data Sheet'!E63,0) -> 5508.33 | G54: =IFERROR('Data Sheet'!F63,0) -> 4136.42 | H54: =IFERROR('Data Sheet'!G63,0) -> 3256.46 | I54: =IFERROR('Data Sheet'!H63,0) -> 4011.29 | J54: =IFERROR('Data Sheet'!I63,0) -> 3225.54 | ... L54: =IFERROR('Data Sheet'!K63,0) -> 2860.78
B55: Investments | C55: =IFERROR('Data Sheet'!B64,0) -> 6942.77 | D55: =IFERROR('Data Sheet'!C64,0) -> 11747.59 | E55: =IFERROR('Data Sheet'!D64,0) -> 17581.38 | F55: =IFERROR('Data Sheet'!E64,0) -> 22052.86 | G55: =IFERROR('Data Sheet'!F64,0) -> 25043.49 | H55: =IFERROR('Data Sheet'!G64,0) -> 28663.35 | I55: =IFERROR('Data Sheet'!H64,0) -> 24870.87 | J55: =IFERROR('Data Sheet'!I64,0) -> 24841.01 | ... L55: =IFERROR('Data Sheet'!K64,0) -> 31114.02
B56: Other Assets | C56: =IFERROR('Data Sheet'!B65-SUM('Data Sheet'!B67:B69),0) -> 2540.81 | D56: =IFERROR('Data Sheet'!C65-SUM('Data Sheet'!C67:C69),0) -> 5194.82 | E56: =IFERROR('Data Sheet'!D65-SUM('Data Sheet'!D67:D69),0) -> 5135.78 | F56: =IFERROR('Data Sheet'!E65-SUM('Data Sheet'!E67:E69),0) -> 7078.75 | G56: =IFERROR('Data Sheet'!F65-SUM('Data Sheet'!F67:F69),0) -> 7138.07 | H56: =IFERROR('Data Sheet'!G65-SUM('Data Sheet'!G67:G69),0) -> 4958.45 | I56: =IFERROR('Data Sheet'!H65-SUM('Data Sheet'!H67:H69),0) -> 4022.24 | J56: =IFERROR('Data Sheet'!I65-SUM('Data Sheet'!I67:I69),0) -> 6917.41 | ... L56: =IFERROR('Data Sheet'!K65-SUM('Data Sheet'!K67:K69),0) -> 4562.57
B57: Total Non Current Assets | C57: =IFERROR(SUM(C53:C56),0) -> 27487.06 | D57: =IFERROR(SUM(D53:D56),0) -> 34608.76 | E57: =IFERROR(SUM(E53:E56),0) -> 42340.53 | F57: =IFERROR(SUM(F53:F56),0) -> 51163.9 | G57: =IFERROR(SUM(G53:G56),0) -> 55692.17 | H57: =IFERROR(SUM(H53:H56),0) -> 58591.6 | I57: =IFERROR(SUM(I53:I56),0) -> 56202.88 | J57: =IFERROR(SUM(J53:J56),0) -> 59215.55 | ... L57: =IFERROR(SUM(L53:L56),0) -> 66357.59
...

Sheet Forecasting
B2: ='Data Sheet'!$B$1&" - "&'Data Sheet'!$A$17&" Forecasting" -> ITC LTD - Sales Forecasting | G2: ='Data Sheet'!$B$1&" - "&'Historical FS'!B18&" Forecasting" -> ITC LTD - EBITDA Forecasting | L2: ='Data Sheet'!$B$1&" - "&'Historical FS'!B38&" Forecasting" -> ITC LTD - Earnings per Share Forecasting
B3: Year Weight | C3: Year | D3: Sales | E3: Sales Growth | G3: Year Weight | H3: Year | I3: EBITDA | J3: EBITDA Growth | L3: Year Weight | M3: Year | N3: EPS | O3: EPS Growth
B4: 1 | C4: ='Data Sheet'!$B$16 -> 42094 | D4: {=TRANSPOSE('Data Sheet'!B17:K17)} -> 38817.15 | G4: 1 | H4: ='Data Sheet'!$B$16 -> 42094 | I4: {=TRANSPOSE('Historical FS'!C18:L18)} -> 14251.62 | L4: 1 | M4: ='Data Sheet'!$B$16 -> 42094 | N4: {=TRANSPOSE('Historical FS'!C38:L38)} -> 7.0997813
B5: 2 | C5: =C4+365 -> 42459 | D5: 39192.1 | E5: =D5/D4-1 -> 0.0096593902 | G5: 2 | H5: =H4+365 -> 42459 | I5: 14531.49 | J5: =I5/I4-1 -> 0.019637767 | L5: 2 | M5: =M4+365 -> 42459 | N5: 6.6422689 | O5: =N5/N4-1 -> -0.064440339
B6: 3 | C6: =C5+365 -> 42824 | D6: 42767.6 | E6: =D6/D5-1 -> 0.09123012 | G6: 3 | H6: =H5+365 -> 42824 | I6: 15469.51 | J6: =I6/I5-1 -> 0.064550848 | L6: 3 | M6: =M5+365 -> 42824 | N6: 7.1773384 | O6: =N6/N5-1 -> 0.080555217
B7: 4 | C7: =C6+365 -> 43189 | D7: 43448.94 | E7: =D7/D6-1 -> 0.015931219 | G7: 4 | H7: =H6+365 -> 43189 | I7: 16520.59 | J7: =I7/I6-1 -> 0.067945268 | L7: 4 | M7: =M6+365 -> 43189 | N7: 7.5816475 | O7: =N7/N6-1 -> 0.056331341
B8: 5 | C8: =C7+365 -> 43554 | D8: 48339.58 | E8: =D8/D7-1 -> 0.11256063 | G8: 5 | H8: =H7+365 -> 43554 | I8: 18537.39 | J8: =I8/I7-1 -> 0.12207796 | L8: 5 | M8: =M7+365 -> 43554 | N8: 8.7738078 | O8: =N8/N7-1 -> 0.15724291
B9: 6 | C9: =C8+365 -> 43919 | D9: 49387.7 | E9: =D9/D8-1 -> 0.021682439 | G9: 6 | H9: =H8+365 -> 43919 | I9: 19343.54 | J9: =I9/I8-1 -> 0.043487783 | L9: 6 | M9: =M8+365 -> 43919 | N9: 10.718553 | O9: =N9/N8-1 -> 0.22165353
B10: 7 | C10: =C9+365 -> 44284 | D10: 49257.45 | E10: =D10/D9-1 -> -0.0026372963 | G10: 7 | H10: =H9+365 -> 44284 | I10: 17064.78 | J10: =I10/I9-1 -> -0.1178047 | L10: 7 | M10: =M9+365 -> 44284 | N10: 8.779028 | O10: =N10/N9-1 -> -0.18095028
B11: 8 | C11: =C10+365 -> 44649 | D11: 60644.54 | E11: =D11/D10-1 -> 0.23117498 | G11: 8 | H11: =H10+365 -> 44649 | I11: 20623.15 | J11: =I11/I10-1 -> 0.20852129 | L11: 8 | M11: =M10+365 -> 44649 | N11: 11.030657 | O11: =N11/N10-1 -> 0.25647821
B12: 9 | C12: =C11+365 -> 45014 | D12: 70919.03 | E12: =D12/D11-1 -> 0.16942152 | G12: 9 | H12: =H11+365 -> 45014 | I12: 25704.26 | J12: =I12/I11-1 -> 0.24637895 | L12: 9 | M12: =M11+365 -> 45014 | N12: 13.983811 | O12: =N12/N11-1 -> 0.26772234
B13: 10 | C13: =C12+365 -> 45379 | D13: 70866.22 | E13: =D13/D12-1 -> -0.00074465203 | G13: 10 | H13: =H12+365 -> 45379 | I13: 26232.56 | J13: =I13/I12-1 -> 0.020553013 | L13: 10 | M13: =M12+365 -> 45379 | N13: 14.375668 | O13: =N13/N12-1 -> 0.028022195
B14: 11 | C14: =C13+365 -> 45744 | D14: =FORECAST(B14,$D$4:$D$13,$B$4:$B$13) -> 71976.981 | E14: =D14/D13-1 -> 0.01567405 | G14: 11 | H14: =H13+365 -> 45744 | I14: =FORECAST(G14,$I$4:$I$13,$G$4:$G$13) -> 25969.381 | J14: =I14/I13-1 -> -0.010032519 | L14: 11 | M14: =M13+365 -> 45744 | N14: =FORECAST(L14,$N$4:$N$13,$L$4:$L$13) -> 14.338831 | O14: =N14/N13-1 -> -0.0025624265
B15: 12 | C15: =C14+365 -> 46109 | D15: =FORECAST(B15,$D$4:$D$13,$B$4:$B$13) -> 75724.79 | E15: =D15/D14-1 -> 0.052069551 | G15: 12 | H15: =H14+365 -> 46109 | I15: =FORECAST(G15,$I$4:$I$13,$G$4:$G$13) -> 27267.834 | J15: =I15/I14-1 -> 0.049999387 | L15: 12 | M15: =M14+365 -> 46109 | N15: =FORECAST(L15,$N$4:$N$13,$L$4:$L$13) -> 15.197481 | O15: =N15/N14-1 -> 0.059882846
B16: 13 | C16: =C15+365 -> 46474 | D16: =FORECAST(B16,$D$4:$D$13,$B$4:$B$13) -> 79472.599 | E16: =D16/D15-1 -> 0.049492498 | G16: 13 | H16: =H15+365 -> 46474 | I16: =FORECAST(G16,$I$4:$I$13,$G$4:$G$13) -> 28566.288 | J16: =I16/I15-1 -> 0.047618492 | L16: 13 | M16: =M15+365 -> 46474 | N16: =FORECAST(L16,$N$4:$N$13,$L$4:$L$13) -> 16.056131 | O16: =N16/N15-1 -> 0.056499495
B17: 14 | C17: =C16+365 -> 46839 | D17: =FORECAST(B17,$D$4:$D$13,$B$4:$B$13) -> 83220.408 | E17: =D17/D16-1 -> 0.047158506 | G17: 14 | H17: =H16+365 -> 46839 | I17: =FORECAST(G17,$I$4:$I$13,$G$4:$G$13) -> 29864.741 | J17: =I17/I16-1 -> 0.045454039 | L17: 14 | M17: =M16+365 -> 46839 | N17: =FORECAST(L17,$N$4:$N$13,$L$4:$L$13) -> 16.914781 | O17: =N17/N16-1 -> 0.053478015
B18: 15 | C18: =C17+365 -> 47204 | D18: =FORECAST(B18,$D$4:$D$13,$B$4:$B$13) -> 86968.217 | E18: =D18/D17-1 -> 0.045034735 | G18: 15 | H18: =H17+365 -> 47204 | I18: =FORECAST(G18,$I$4:$I$13,$G$4:$G$13) -> 31163.194 | J18: =I18/I17-1 -> 0.043477797 | L18: 15 | M18: =M17+365 -> 47204 | N18: =FORECAST(L18,$N$4:$N$13,$L$4:$L$13) -> 17.773431 | O18: =N18/N17-1 -> 0.050763294

Sheet Ratio Analysis
B2: ="Ratio Analysis of - "&'Data Sheet'!$B$1 -> Ratio Analysis of - ITC LTD
B3: Years | C3: ='Data Sheet'!B16 -> 42094 | D3: ='Data Sheet'!C16 -> 42460 | E3: ='Data Sheet'!D16 -> 42825 | F3: ='Data Sheet'!E16 -> 43190 | G3: ='Data Sheet'!F16 -> 43555 | H3: ='Data Sheet'!G16 -> 43921 | I3: ='Data Sheet'!H16 -> 44286 | J3: ='Data Sheet'!I16 -> 44651 | ... L3: ='Data Sheet'!K16 -> 45382 | M3: Trend | N3: Mean | O3: Median
B5: Sales Growth | D5: =IFERROR('Historical FS'!D6/'Historical FS'!C6-1,0) -> 0.0096593902 | E5: =IFERROR('Historical FS'!E6/'Historical FS'!D6-1,0) -> 0.09123012 | F5: =IFERROR('Historical FS'!F6/'Historical FS'!E6-1,0) -> 0.015931219 | G5: =IFERROR('Historical FS'!G6/'Historical FS'!F6-1,0) -> 0.11256063 | H5: =IFERROR('Historical FS'!H6/'Historical FS'!G6-1,0) -> 0.021682439 | I5: =IFERROR('Historical FS'!I6/'Historical FS'!H6-1,0) -> -0.0026372963 | J5: =IFERROR('Historical FS'!J6/'Historical FS'!I6-1,0) -> 0.23117498 | K5: =IFERROR('Historical FS'!K6/'Historical FS'!J6-1,0) -> 0.16942152 | L5: =IFERROR('Historical FS'!L6/'Historical FS'!K6-1,0) -> -0.00074465203 | N5: =IFERROR(AVERAGE(D5:L5),0) -> 0.072030927 | O5: =IFERROR(MEDIAN(D5:L5),0) -> 0.021682439
B6: EBITDA Growth | D6: =IFERROR('Historical FS'!D18/'Historical FS'!C18-1,0) -> 0.019637767 | E6: =IFERROR('Historical FS'!E18/'Historical FS'!D18-1,0) -> 0.064550848 | F6: =IFERROR('Historical FS'!F18/'Historical FS'!E18-1,0) -> 0.067945268 | G6: =IFERROR('Historical FS'!G18/'Historical FS'!F18-1,0) -> 0.12207796 | H6: =IFERROR('Historical FS'!H18/'Historical FS'!G18-1,0) -> 0.043487783 | I6: =IFERROR('Historical FS'!I18/'Historical FS'!H18-1,0) -> -0.1178047 | J6: =IFERROR('Historical FS'!J18/'Historical FS'!I18-1,0) -> 0.20852129 | K6: =IFERROR('Historical FS'!K18/'Historical FS'!J18-1,0) -> 0.24637895 | L6: =IFERROR('Historical FS'!L18/'Historical FS'!K18-1,0) -> 0.020553013 | N6: =IFERROR(AVERAGE(D6:L6),0) -> 0.075038687 | O6: =IFERROR(MEDIAN(D6:L6),0) -> 0.064550848
B7: EBIT Growth | D7: =IFERROR(('Historical FS'!D18-'Historical FS'!D24)/('Historical FS'!C18-'Historical FS'!C24)-1,0) -> 0.017425584 | E7: =IFERROR(('Historical FS'!E18-'Historical FS'!E24)/('Historical FS'!D18-'Historical FS'!D24)-1,0) -> 0.064116562 | F7: =IFERROR(('Historical FS'!F18-'Historical FS'!F24)/('Historical FS'!E18-'Historical FS'!E24)-1,0) -> 0.067584614 | G7: =IFERROR(('Historical FS'!G18-'Historical FS'!G24)/('Historical FS'!F18-'Historical FS'!F24)-1,0) -> 0.12146247 | H7: =IFERROR(('Historical FS'!H18-'Historical FS'!H24)/('Historical FS'!G18-'Historical FS'!G24)-1,0) -> 0.032545193 | I7: =IFERROR(('Historical FS'!I18-'Historical FS'!I24)/('Historical FS'!H18-'Historical FS'!H24)-1,0) -> -0.12879189 | J7: =IFERROR(('Historical FS'!J18-'Historical FS'!J24)/('Historical FS'!I18-'Historical FS'!I24)-1,0) -> 0.22514477 | K7: =IFERROR(('Historical FS'!K18-'Historical FS'!K24)/('Historical FS'!J18-'Historical FS'!J24)-1,0) -> 0.26491869 | L7: =IFERROR(('Historical FS'!L18-'Historical FS'!L24)/('Historical FS'!K18-'Historical FS'!K24)-1,0) -> 0.021800149 | N7: =IFERROR(AVERAGE(D7:L7),0) -> 0.076245126 | O7: =IFERROR(MEDIAN(D7:L7),0) -> 0.064116562
B8: Net Profit Growth | D8: =IFERROR('Historical FS'!D33/'Historical FS'!C33-1,0) -> -0.060744259 | E8: =IFERROR('Historical FS'!E33/'Historical FS'!D33-1,0) -> 0.087412304 | F8: =IFERROR('Historical FS'!F33/'Historical FS'!E33-1,0) -> 0.061279334 | G8: =IFERROR('Historical FS'!G33/'Historical FS'!F33-1,0) -> 0.16239178 | H8: =IFERROR('Historical FS'!H33/'Historical FS'!G33-1,0) -> 0.225002 | I8: =IFERROR('Historical FS'!I33/'Historical FS'!H33-1,0) -> -0.1798442 | J8: =IFERROR('Historical FS'!J33/'Historical FS'!I33-1,0) -> 0.25795836 | K8: =IFERROR('Historical FS'!K33/'Historical FS'!J33-1,0) -> 0.27849303 | L8: =IFERROR('Historical FS'!L33/'Historical FS'!K33-1,0) -> 0.032712318 | N8: =IFERROR(AVERAGE(D8:L8),0) -> 0.096073408 | O8: =IFERROR(MEDIAN(D8:L8),0) -> 0.087412304
B9: Dividend Growth | D9: =IFERROR('Historical FS'!D41/'Historical FS'!C41-1,0) -> 0.35676799 | E9: =IFERROR('Historical FS'!E41/'Historical FS'!D41-1,0) -> -0.16037752 | F9: =IFERROR('Historical FS'!F41/'Historical FS'!E41-1,0) -> 0.08446234 | G9: =IFERROR('Historical FS'!G41/'Historical FS'!F41-1,0) -> 0.11840858 | H9: =IFERROR('Historical FS'!H41/'Historical FS'!G41-1,0) -> 0.76766691 | I9: =IFERROR('Historical FS'!I41/'Historical FS'!H41-1,0) -> 0.059295964 | J9: =IFERROR('Historical FS'!J41/'Historical FS'!I41-1,0) -> 0.062005123 | K9: =IFERROR('Historical FS'!K41/'Historical FS'!J41-1,0) -> 0.35310364 | L9: =IFERROR('Historical FS'!L41/'Historical FS'!K41-1,0) -> -0.10885617 | N9: =IFERROR(AVERAGE(D9:L9),0) -> 0.17027521 | O9: =IFERROR(MEDIAN(D9:L9),0) -> 0.08446234
B11: Gross Margin | C11: =IFERROR('Historical FS'!C13,0) -> 0.49279172 | D11: =IFERROR('Historical FS'!D13,0) -> 0.51105095 | E11: =IFERROR('Historical FS'!E13,0) -> 0.48678158 | F11: =IFERROR('Historical FS'!F13,0) -> 0.49440654 | G11: =IFERROR('Historical FS'!G13,0) -> 0.49904509 | H11: =IFERROR('Historical FS'!H13,0) -> 0.50735912 | I11: =IFERROR('Historical FS'!I13,0) -> 0.45426509 | J11: =IFERROR('Historical FS'!J13,0) -> 0.43848102 | ... L11: =IFERROR('Historical FS'!L13,0) -> 0.47767103 | N11: =IFERROR(AVERAGE(C11:L11),0) -> 0.48217696 | O11: =IFERROR(MEDIAN(C11:L11),0) -> 0.48978665
B12: EBITDA Margin | C12: =IFERROR('Historical FS'!C19,0) -> 0.36714751 | D12: =IFERROR('Historical FS'!D19,0) -> 0.370776 | E12: =IFERROR('Historical FS'!E19,0) -> 0.36171097 | F12: =IFERROR('Historical FS'!F19,0) -> 0.38022999 | G12: =IFERROR('Historical FS'!G19,0) -> 0.38348265 | H12: =IFERROR('Historical FS'!H19,0) -> 0.39166716 | I12: =IFERROR('Historical FS'!I19,0) -> 0.34644059 | J12: =IFERROR('Historical FS'!J19,0) -> 0.34006606 | ... L12: =IFERROR('Historical FS'!L19,0) -> 0.37017016 | N12: =IFERROR(AVERAGE(C12:L12),0) -> 0.36741363 | O12: =IFERROR(MEDIAN(C12:L12),0) -> 0.36865884
B13: EBIT Margin | C13: =IFERROR(('Historical FS'!C18-'Historical FS'!C24)/'Historical FS'!C6,0) -> 0.3406654 | D13: =IFERROR(('Historical FS'!D18-'Historical FS'!D24)/'Historical FS'!D6,0) -> 0.34328576 | E13: =IFERROR(('Historical FS'!E18-'Historical FS'!E24)/'Historical FS'!E6,0) -> 0.33475622 | F13: =IFERROR(('Historical FS'!F18-'Historical FS'!F24)/'Historical FS'!F6,0) -> 0.35177636 | G13: =IFERROR(('Historical FS'!G18-'Historical FS'!G24)/'Historical FS'!G6,0) -> 0.354591 | H13: =IFERROR(('Historical FS'!H18-'Historical FS'!H24)/'Historical FS'!H6,0) -> 0.35836109 | I13: =IFERROR(('Historical FS'!I18-'Historical FS'!I24)/'Historical FS'!I6,0) -> 0.31303265 | J13: =IFERROR(('Historical FS'!J18-'Historical FS'!J24)/'Historical FS'!J6,0) -> 0.31149944 | ... L13: =IFERROR(('Historical FS'!L18-'Historical FS'!L24)/'Historical FS'!L6,0) -> 0.34453891 | N13: =IFERROR(AVERAGE(C13:L13),0) -> 0.33894439 | O13: =IFERROR(MEDIAN(C13:L13),0) -> 0.34197558
B14: EBT Margin | C14: =IFERROR('Historical FS'!C28,0) -> 0.33832211 | D14: =IFERROR('Historical FS'!D28,0) -> 0.34129225 | E14: =IFERROR('Historical FS'!E28,0) -> 0.33360979 | F14: =IFERROR('Historical FS'!F28,0) -> 0.34912935 | G14: =IFERROR('Historical FS'!G28,0) -> 0.35311395 | H14: =IFERROR('Historical FS'!H28,0) -> 0.35671331 | I14: =IFERROR('Historical FS'!I28,0) -> 0.31185577 | J14: =IFERROR('Historical FS'!J28,0) -> 0.31051023 | ... L14: =IFERROR('Historical FS'!L28,0) -> 0.34340917 | N14: =IFERROR(AVERAGE(C14:L14),0) -> 0.33737964 | O14: =IFERROR(MEDIAN(C14:L14),0) -> 0.33980718
B15: Net Profit Margin | C15: =IFERROR('Historical FS'!C34,0) -> 0.21991001 | D15: =IFERROR('Historical FS'!D34,0) -> 0.20457567 | E15: =IFERROR('Historical FS'!E34,0) -> 0.20385993 | F15: =IFERROR('Historical FS'!F34,0) -> 0.21295963 | G15: =IFERROR('Historical FS'!G34,0) -> 0.222498 | H15: =IFERROR('Historical FS'!H34,0) -> 0.26677614 | I15: =IFERROR('Historical FS'!I34,0) -> 0.21937656 | J15: =IFERROR('Historical FS'!J34,0) -> 0.22414895 | ... L15: =IFERROR('Historical FS'!L34,0) -> 0.25326016 | N15: =IFERROR(AVERAGE(C15:L15),0) -> 0.22724203 | O15: =IFERROR(MEDIAN(C15:L15),0) -> 0.22120401
B17: Sales Expenses % Sales | C17: =IFERROR('Historical FS'!C16,0) -> 0.12564421 | D17: =IFERROR('Historical FS'!D16,0) -> 0.14027495 | E17: =IFERROR('Historical FS'!E16,0) -> 0.12507061 | F17: =IFERROR('Historical FS'!F16,0) -> 0.11417655 | G17: =IFERROR('Historical FS'!G16,0) -> 0.11556244 | H17: =IFERROR('Historical FS'!H16,0) -> 0.11569196 | I17: =IFERROR('Historical FS'!I16,0) -> 0.1078245 | J17: =IFERROR('Historical FS'!J16,0) -> 0.09841496 | ... L17: =IFERROR('Historical FS'!L16,0) -> 0.10750087 | N17: =IFERROR(AVERAGE(C17:L17),0) -> 0.11476333 | O17: =IFERROR(MEDIAN(C17:L17),0) -> 0.1148695
B18: Depreciation % Sales | C18: =IFERROR('Historical FS'!C25,0) -> 0.026482109 | D18: =IFERROR('Historical FS'!D25,0) -> 0.027490234 | E18: =IFERROR('Historical FS'!E25,0) -> 0.026954751 | F18: =IFERROR('Historical FS'!F25,0) -> 0.028453629 | G18: =IFERROR('Historical FS'!G25,0) -> 0.028891645 | H18: =IFERROR('Historical FS'!H25,0) -> 0.033306066 | I18: =IFERROR('Historical FS'!I25,0) -> 0.033407941 | J18: =IFERROR('Historical FS'!J25,0) -> 0.028566628 | ... L18: =IFERROR('Historical FS'!L25,0) -> 0.025631253 | N18: =IFERROR(AVERAGE(C18:L18),0) -> 0.028469236 | O18: =IFERROR(MEDIAN(C18:L18),0) -> 0.027971931
B19: Operating Income % Sales | C19: =IFERROR('Ratio Analysis'!C13,0) -> 0.3406654 | D19: =IFERROR('Ratio Analysis'!D13,0) -> 0.34328576 | E19: =IFERROR('Ratio Analysis'!E13,0) -> 0.33475622 | F19: =IFERROR('Ratio Analysis'!F13,0) -> 0.35177636 | G19: =IFERROR('Ratio Analysis'!G13,0) -> 0.354591 | H19: =IFERROR('Ratio Analysis'!H13,0) -> 0.35836109 | I19: =IFERROR('Ratio Analysis'!I13,0) -> 0.31303265 | J19: =IFERROR('Ratio Analysis'!J13,0) -> 0.31149944 | ... L19: =IFERROR('Ratio Analysis'!L13,0) -> 0.34453891 | N19: =IFERROR(AVERAGE(C19:L19),0) -> 0.33894439 | O19: =IFERROR(MEDIAN(C19:L19),0) -> 0.34197558
B21: Return on Capital Employed | C21: =IFERROR(('Historical FS'!C18-'Historical FS'!C24)/(SUM('Historical FS'!C47:C49)),0) -> 0.41318398 | D21: =IFERROR(('Historical FS'!D18-'Historical FS'!D24)/(SUM('Historical FS'!D47:D49)),0) -> 0.31461767 | E21: =IFERROR(('Historical FS'!E18-'Historical FS'!E24)/(SUM('Historical FS'!E47:E49)),0) -> 0.30816048 | F21: =IFERROR(('Historical FS'!F18-'Historical FS'!F24)/(SUM('Historical FS'!F47:F49)),0) -> 0.29087469 | G21: =IFERROR(('Historical FS'!G18-'Historical FS'!G24)/(SUM('Historical FS'!G47:G49)),0) -> 0.28976384 | H21: =IFERROR(('Historical FS'!H18-'Historical FS'!H24)/(SUM('Historical FS'!H47:H49)),0) -> 0.26999906 | I21: =IFERROR(('Historical FS'!I18-'Historical FS'!I24)/(SUM('Historical FS'!I47:I49)),0) -> 0.25436581 | J21: =IFERROR(('Historical FS'!J18-'Historical FS'!J24)/(SUM('Historical FS'!J47:J49)),0) -> 0.30126365 | ... L21: =IFERROR(('Historical FS'!L18-'Historical FS'!L24)/(SUM('Historical FS'!L47:L49)),0) -> 0.32637388 | N21: =IFERROR(AVERAGE(C21:L21),0) -> 0.31126112 | O21: =IFERROR(MEDIAN(C21:L21),0) -> 0.30471206
B22: Retained Earnings% | C22: =IFERROR('Historical FS'!C44,0) -> 0.41543901 | D22: =IFERROR('Historical FS'!D44,0) -> 0.15225755 | E22: =IFERROR('Historical FS'!E44,0) -> 0.34127974 | F22: =IFERROR('Historical FS'!F44,0) -> 0.32373746 | G22: =IFERROR('Historical FS'!G44,0) -> 0.34643123 | H22: =IFERROR('Historical FS'!H44,0) -> 0.05432116 | I22: =IFERROR('Historical FS'!I44,0) -> 0 | J22: =IFERROR('Historical FS'!J44,0) -> 0 | ... L22: =IFERROR('Historical FS'!L44,0) -> 0.043522835 | N22: =IFERROR(AVERAGE(C22:L22),0) -> 0.1676989 | O22: =IFERROR(MEDIAN(C22:L22),0) -> 0.10328935
B23: Return on Equity% | C23: =IFERROR('Historical FS'!C33/SUM('Historical FS'!C47:C48),0) -> 0.26898214 | D23: =IFERROR('Historical FS'!D33/SUM('Historical FS'!D47:D48),0) -> 0.18785942 | E23: =IFERROR('Historical FS'!E33/SUM('Historical FS'!E47:E48),0) -> 0.18784852 | F23: =IFERROR('Historical FS'!F33/SUM('Historical FS'!F47:F48),0) -> 0.17621121 | G23: =IFERROR('Historical FS'!G33/SUM('Historical FS'!G47:G48),0) -> 0.18186171 | H23: =IFERROR('Historical FS'!H33/SUM('Historical FS'!H47:H48),0) -> 0.2018508 | I23: =IFERROR('Historical FS'!I33/SUM('Historical FS'!I47:I48),0) -> 0.17906224 | J23: =IFERROR('Historical FS'!J33/SUM('Historical FS'!J47:J48),0) -> 0.21764928 | ... L23: =IFERROR('Historical FS'!L33/SUM('Historical FS'!L47:L48),0) -> 0.24088461 | N23: =IFERROR(AVERAGE(C23:L23),0) -> 0.20935152 | O23: =IFERROR(MEDIAN(C23:L23),0) -> 0.19485511
B24: Self Sustained Growth Rate | C24: =IFERROR(C22*C23,0) -> 0.11174567 | D24: =IFERROR(D22*D23,0) -> 0.028603015 | E24: =IFERROR(E22*E23,0) -> 0.064108892 | F24: =IFERROR(F22*F23,0) -> 0.057046169 | G24: =IFERROR(G22*G23,0) -> 0.063002577 | H24: =IFERROR(H22*H23,0) -> 0.01096477 | I24: =IFERROR(I22*I23,0) -> 0 | J24: =IFERROR(J22*J23,0) -> 0 | ... L24: =IFERROR(L22*L23,0) -> 0.010483981 | N24: =IFERROR(AVERAGE(C24:L24),0) -> 0.034595508 | O24: =IFERROR(MEDIAN(C24:L24),0) -> 0.019783892
B25: Interest Coverage Ratio | C25: =IFERROR(('Historical FS'!C18-'Historical FS'!C25)/'Historical FS'!C21,0) -> 156.67979 | D25: =IFERROR(('Historical FS'!D18-'Historical FS'!D25)/'Historical FS'!D21,0) -> 185.99082 | E25: =IFERROR(('Historical FS'!E18-'Historical FS'!E25)/'Historical FS'!E21,0) -> 315.51057 | F25: =IFERROR(('Historical FS'!F18-'Historical FS'!F25)/'Historical FS'!F21,0) -> 143.64457 | G25: =IFERROR(('Historical FS'!G18-'Historical FS'!G25)/'Historical FS'!G21,0) -> 259.62691 | H25: =IFERROR(('Historical FS'!H18-'Historical FS'!H25)/'Historical FS'!H21,0) -> 237.69362 | I25: =IFERROR(('Historical FS'!I18-'Historical FS'!I25)/'Historical FS'!I21,0) -> 294.37203 | J25: =IFERROR(('Historical FS'!J18-'Historical FS'!J25)/'Historical FS'!J21,0) -> 343.77599 | ... L25: =IFERROR(('Historical FS'!L18-'Historical FS'!L25)/'Historical FS'!L21,0) -> 327.66093 | N25: =IFERROR(AVERAGE(C25:L25),0) -> 259.54713 | O25: =IFERROR(MEDIAN(C25:L25),0) -> 276.99947
B27: Debtor Turnover Ratio | C27: =IFERROR('Historical FS'!C6/'Historical FS'!C59,0) -> 19.584147 | D27: =IFERROR('Historical FS'!D6/'Historical FS'!D59,0) -> 20.442577 | E27: =IFERROR('Historical FS'!E6/'Historical FS'!E59,0) -> 17.284797 | F27: =IFERROR('Historical FS'!F6/'Historical FS'!F59,0) -> 16.19845 | G27: =IFERROR('Historical FS'!G6/'Historical FS'!G59,0) -> 11.979238 | H27: =IFERROR('Historical FS'!H6/'Historical FS'!H59,0) -> 19.273399 | I27: =IFERROR('Historical FS'!I6/'Historical FS'!I59,0) -> 19.689591 | J27: =IFERROR('Historical FS'!J6/'Historical FS'!J59,0) -> 24.633226 | ... L27: =IFERROR('Historical FS'!L6/'Historical FS'!L59,0) -> 17.602928 | N27: =IFERROR(AVERAGE(C27:L27),0) -> 19.067853 | O27: =IFERROR(MEDIAN(C27:L27),0) -> 19.428773
B28: Creditor Turnover Ratio | C28: =IFERROR('Historical FS'!C6/'Historical FS'!C50,0) -> 2.7830044 | D28: =IFERROR('Historical FS'!D6/'Historical FS'!D50,0) -> 4.4095324 | E28: =IFERROR('Historical FS'!E6/'Historical FS'!E50,0) -> 4.5306245 | F28: =IFERROR('Historical FS'!F6/'Historical FS'!F50,0) -> 3.7152199 | G28: =IFERROR('Historical FS'!G6/'Historical FS'!G50,0) -> 3.8411297 | H28: =IFERROR('Historical FS'!H6/'Historical FS'!H50,0) -> 4.1996201 | I28: =IFERROR('Historical FS'!I6/'Historical FS'!I50,0) -> 3.7479256 | J28: =IFERROR('Historical FS'!J6/'Historical FS'!J50,0) -> 4.1849768 | ... L28: =IFERROR('Historical FS'!L6/'Historical FS'!L50,0) -> 4.182492 | N28: =IFERROR(AVERAGE(C28:L28),0) -> 3.9926871 | O28: =IFERROR(MEDIAN(C28:L28),0) -> 4.1837344
B29: Inventory Turnover | C29: =IFERROR('Historical FS'!C9/'Historical FS'!C60,0) -> 2.2928471 | D29: =IFERROR('Historical FS'!D9/'Historical FS'!D60,0) -> 2.1146246 | E29: =IFERROR('Historical FS'!E9/'Historical FS'!E60,0) -> 2.7043925 | F29: =IFERROR('Historical FS'!F9/'Historical FS'!F60,0) -> 2.9309188 | G29: =IFERROR('Historical FS'!G9/'Historical FS'!G60,0) -> 3.0810821 | H29: =IFERROR('Historical FS'!H9/'Historical FS'!H60,0) -> 2.7401167 | I29: =IFERROR('Historical FS'!I9/'Historical FS'!I60,0) -> 2.5854666 | J29: =IFERROR('Historical FS'!J9/'Historical FS'!J60,0) -> 3.1344431 | ... L29: =IFERROR('Historical FS'!L9/'Historical FS'!L60,0) -> 2.6154027 | N29: =IFERROR(AVERAGE(C29:L29),0) -> 2.745319 | O29: =IFERROR(MEDIAN(C29:L29),0) -> 2.7222546
B30: Fixed Asset Turnover | C30: =IFERROR('Historical FS'!C6/'Historical FS'!C53,0) -> 2.5365248 | D30: =IFERROR('Historical FS'!D6/'Historical FS'!D53,0) -> 2.5943642 | E30: =IFERROR('Historical FS'!E6/'Historical FS'!E53,0) -> 2.6908896 | F30: =IFERROR('Historical FS'!F6/'Historical FS'!F53,0) -> 2.6294508 | G30: =IFERROR('Historical FS'!G6/'Historical FS'!G53,0) -> 2.4950504 | H30: =IFERROR('Historical FS'!H6/'Historical FS'!H53,0) -> 2.2745326 | I30: =IFERROR('Historical FS'!I6/'Historical FS'!I53,0) -> 2.1141916 | J30: =IFERROR('Historical FS'!J6/'Historical FS'!J53,0) -> 2.5027058 | ... L30: =IFERROR('Historical FS'!L6/'Historical FS'!L53,0) -> 2.5472919 | N30: =IFERROR(AVERAGE(C30:L30),0) -> 2.512835 | O30: =IFERROR(MEDIAN(C30:L30),0) -> 2.5419084
B31: Capital Turnover Ratio | C31: =IFERROR('Historical FS'!C6/SUM('Historical FS'!C47:C48),0) -> 1.2231464 | D31: =IFERROR('Historical FS'!D6/SUM('Historical FS'!D47:D48),0) -> 0.91828821 | E31: =IFERROR('Historical FS'!E6/SUM('Historical FS'!E47:E48),0) -> 0.92145874 | F31: =IFERROR('Historical FS'!F6/SUM('Historical FS'!F47:F48),0) -> 0.82743952 | G31: =IFERROR('Historical FS'!G6/SUM('Historical FS'!G47:G48),0) -> 0.81736336 | H31: =IFERROR('Historical FS'!H6/SUM('Historical FS'!H47:H48),0) -> 0.7566299 | I31: =IFERROR('Historical FS'!I6/SUM('Historical FS'!I47:I48),0) -> 0.81623233 | J31: =IFERROR('Historical FS'!J6/SUM('Historical FS'!J47:J48),0) -> 0.97100291 | ... L31: =IFERROR('Historical FS'!L6/SUM('Historical FS'!L47:L48),0) -> 0.95113506 | N31: =IFERROR(AVERAGE(C31:L31),0) -> 0.92282009 | O31: =IFERROR(MEDIAN(C31:L31),0) -> 0.91987347
B33: Debtor Days | C33: =IFERROR(365/C27,0) -> 18.637524 | D33: =IFERROR(365/D27,0) -> 17.854892 | E33: =IFERROR(365/E27,0) -> 21.116823 | F33: =IFERROR(365/F27,0) -> 22.53302 | G33: =IFERROR(365/G27,0) -> 30.469383 | H33: =IFERROR(365/H27,0) -> 18.938019 | I33: =IFERROR(365/I27,0) -> 18.537714 | J33: =IFERROR(365/J27,0) -> 14.817385 | ... L33: =IFERROR(365/L27,0) -> 20.735187 | N33: =IFERROR(AVERAGE(C33:L33),0) -> 19.885451 | O33: =IFERROR(MEDIAN(C33:L33),0) -> 18.787771
B34: Payable Days | C34: =IFERROR(365/C28,0) -> 131.15323 | D34: =IFERROR(365/D28,0) -> 82.775217 | E34: =IFERROR(365/E28,0) -> 80.562845 | F34: =IFERROR(365/F28,0) -> 98.24452 | G34: =IFERROR(365/G28,0) -> 95.024128 | H34: =IFERROR(365/H28,0) -> 86.912624 | I34: =IFERROR(365/I28,0) -> 97.387204 | J34: =IFERROR(365/J28,0) -> 87.216733 | ... L34: =IFERROR(365/L28,0) -> 87.268548 | N34: =IFERROR(AVERAGE(C34:L34),0) -> 93.079501 | O34: =IFERROR(MEDIAN(C34:L34),0) -> 87.24264
B35: Inventory Days | C35: =IFERROR(365/C29,0) -> 159.19073 | D35: =IFERROR(365/D29,0) -> 172.60747 | E35: =IFERROR(365/E29,0) -> 134.96562 | F35: =IFERROR(365/F29,0) -> 124.53433 | G35: =IFERROR(365/G29,0) -> 118.46487 | H35: =IFERROR(365/H29,0) -> 133.20601 | I35: =IFERROR(365/I29,0) -> 141.17374 | J35: =IFERROR(365/J29,0) -> 116.44812 | ... L35: =IFERROR(365/L29,0) -> 139.55786 | N35: =IFERROR(AVERAGE(C35:L35),0) -> 135.2322 | O35: =IFERROR(MEDIAN(C35:L35),0) -> 134.08581
B36: Cash Conversion Cycle (in days) | C36: =SUM(C33,C35)-C34 -> 46.675026 | D36: =SUM(D33,D35)-D34 -> 107.68714 | E36: =SUM(E33,E35)-E34 -> 75.519594 | F36: =SUM(F33,F35)-F34 -> 48.822828 | G36: =SUM(G33,G35)-G34 -> 53.910127 | H36: =SUM(H33,H35)-H34 -> 65.231403 | I36: =SUM(I33,I35)-I34 -> 62.324253 | J36: =SUM(J33,J35)-J34 -> 44.04877 | ... L36: =SUM(L33,L35)-L34 -> 73.0245 | N36: =IFERROR(AVERAGE(C36:L36),0) -> 62.038146 | O36: =IFERROR(MEDIAN(C36:L36),0) -> 58.11719
